<?xml version="1.0" ?>
<robot name="irb_6640" xmlns:xacro="http://ros.org/wiki/xacro">

  <!-- ##################LINK################## -->

  <link name="world"/>
  <link name="support">
    <visual>
      <geometry>
        <box size="1 1 0.05"/>
      </geometry>
    </visual>
    <collision>
      <geometry>
        <box size="1 1 0.05"/>
      </geometry>
    </collision>
    <inertial>
      <mass value="600"/>
      <origin rpy="0 0 0" xyz="0 0 0"/>
      <inertia ixx="0.1315" ixy="0" ixz="0" iyy="0.1415" iyz="0" izz="0.02"/>
    </inertial>
  </link>

  <link name="lwr_base_link">
    <inertial>
      <mass value="500"/>
      <origin rpy="0 0 0" xyz="0.18 0.15 0.41"/>
      <inertia ixx="0.1315" ixy="0" ixz="0" iyy="0.1415" iyz="0" izz="0.02"/>
    </inertial>
    <visual>
      <geometry>
        <mesh filename="/home/geekayman/based_on_flobaroid/model/meshes/irb6640_185_280/visual/base_link.stl"/>
      </geometry>
      <material name="">
        <color rgba="0.7372549 0.3490196 0.1607843 1"/>
      </material>
    </visual>
    <collision>
      <geometry>
        <mesh filename="/home/geekayman/based_on_flobaroid/model/meshes/irb6640_185_280/collision/base_link.stl"/>
      </geometry>
    </collision>
  </link>

  <link name="lwr_1_link">
    <inertial>
      <mass value="411"/>
      <origin rpy="0 0 0" xyz="0.18 0.15 0.41"/>
      <inertia ixx="0.1315" ixy="0" ixz="0" iyy="0.1415" iyz="0" izz="0.02"/>
    </inertial>
    <visual>
      <geometry>
        <mesh filename="/home/geekayman/based_on_flobaroid/model/meshes/irb6640_185_280/visual/link_1.stl"/>
      </geometry>
      <material name="">
        <color rgba="0.7372549 0.3490196 0.1607843 1"/>
      </material>
    </visual>
    <collision>
      <geometry>
        <mesh filename="/home/geekayman/based_on_flobaroid/model/meshes/irb6640_185_280/collision/link_1.stl"/>
      </geometry>
    </collision>
  </link>

  <link name="lwr_2_link">
    <inertial>
      <mass value="121"/>
      <origin rpy="0 0 0" xyz="0.55 0 0.1"/>
      <inertia ixx="0.02" ixy="0" ixz="0" iyy="0.3962" iyz="0" izz="0.3952"/>
    </inertial>
    <visual>
      <geometry>
        <mesh filename="/home/geekayman/based_on_flobaroid/model/meshes/irb6640_185_280/visual/link_2.stl"/>
      </geometry>
      <material name="">
        <color rgba="0.7372549 0.3490196 0.1607843 1"/>
      </material>
    </visual>
    <collision>
      <geometry>
        <mesh filename="/home/geekayman/based_on_flobaroid/model/meshes/irb6640_185_280/collision/link_2.stl"/>
      </geometry>
    </collision>
  </link>

  <link name="lwr_3_link">
    <inertial>
      <mass value="113.4"/>
      <origin rpy="0 0 0" xyz="0.18 0.11 0.01"/>
      <inertia ixx="0.045" ixy="0" ixz="0" iyy="0.04" iyz="0" izz="0.012"/>
    </inertial>
    <visual>
      <geometry>
        <mesh filename="/home/geekayman/based_on_flobaroid/model/meshes/irb6640_185_280/visual/link_3.stl"/>
      </geometry>
      <material name="">
        <color rgba="0.7372549 0.3490196 0.1607843 1"/>
      </material>
    </visual>
    <collision>
      <geometry>
        <mesh filename="/home/geekayman/based_on_flobaroid/model/meshes/irb6640_185_280/collision/link_3.stl"/>
      </geometry>
    </collision>
  </link>

  <link name="lwr_4_link">
    <inertial>
      <mass value="74.6"/>
      <origin rpy="0 0 0" xyz="0 0 0.41"/>
      <inertia ixx="0.437" ixy="0" ixz="0" iyy="0.447" iyz="0" izz="0.02"/>
    </inertial>
    <visual>
      <geometry>
        <mesh filename="/home/geekayman/based_on_flobaroid/model/meshes/irb6640_185_280/visual/link_4.stl"/>
      </geometry>
      <material name="">
        <color rgba="0.7372549 0.3490196 0.1607843 1"/>
      </material>
    </visual>
    <collision>
      <geometry>
        <mesh filename="/home/geekayman/based_on_flobaroid/model/meshes/irb6640_185_280/collision/link_4.stl"/>
      </geometry>
    </collision>
  </link>

  <link name="lwr_5_link">
    <inertial>
      <mass value="24.6"/>
      <origin rpy="0 0 0" xyz="0 0.05 0"/>
      <inertia ixx="0.0133" ixy="0" ixz="0" iyy="0.025" iyz="0" izz="0.02"/>
    </inertial>
    <visual>
      <geometry>
        <mesh filename="/home/geekayman/based_on_flobaroid/model/meshes/irb6640_185_280/visual/link_5.stl"/>
      </geometry>
      <material name="">
        <color rgba="0.7372549 0.3490196 0.1607843 1"/>
      </material>
    </visual>
    <collision>
      <geometry>
        <mesh filename="/home/geekayman/based_on_flobaroid/model/meshes/irb6640_185_280/collision/link_5.stl"/>
      </geometry>
    </collision>
  </link>

  <link name="lwr_6_link">
    <inertial>
      <mass value="5"/>
      <origin rpy="0 0 0" xyz="0 0 0.02"/>
      <inertia ixx="0.02" ixy="0" ixz="0" iyy="0.02" iyz="0" izz="0.0253"/>
    </inertial>
    <visual>
      <geometry>
        <mesh filename="/home/geekayman/based_on_flobaroid/model/meshes/irb6640_185_280/visual/link_6.stl"/>
      </geometry>
      <material name="">
        <color rgba="0.5 0.5 0.5 1"/>
      </material>
    </visual>
    <collision>
      <geometry>
        <mesh filename="/home/geekayman/based_on_flobaroid/model/meshes/irb6640_185_280/collision/link_6.stl"/>
      </geometry>
    </collision>
  </link>
  <link name="link_cylinder">
    <inertial>
      <mass value="210"/>
      <origin rpy="0 0 0" xyz="0 0 0.65"/>
      <inertia ixx="0.9" ixy="0" ixz="0" iyy="0.9" iyz="0" izz="0.9"/>
    </inertial>
    <collision name="collision">
      <geometry>
        <mesh filename="/home/geekayman/based_on_flobaroid/model/meshes/irb6640_185_280/collision/cylinder_link.stl"/>
      </geometry>
      <material name="yellow"/>
    </collision>
    <visual name="visual">
      <geometry>
        <mesh filename="/home/geekayman/based_on_flobaroid/model/meshes/irb6640_185_280/visual/cylinder.stl"/>
      </geometry>
      <material name="orange"/>
    </visual>
  </link>

  <joint name="box_support" type="fixed">
    <origin rpy="0 0 0" xyz="0 0 0"/>
    <parent link="world"/>
    <child link="support"/>
  </joint>
  <joint name="base_joint_support" type="fixed">
    <origin rpy="0 0 0" xyz="0 0 0"/>
    <parent link="support"/>
    <child link="lwr_base_link"/>
  </joint>
  <joint name="lwr_0_joint" type="revolute">
    <origin rpy="0 0 0" xyz="0 0 0.227"/>
    <axis xyz="0 0 1"/>
    <limit effort="6700" lower="-2.967" upper="2.967" velocity="1.7453"/>
    <dynamics damping="1.0" friction="0.0"/>
    <parent link="lwr_base_link"/>
    <child link="lwr_1_link"/>
  </joint>
  <joint name="lwr_1_joint" type="revolute">
    <origin rpy="0 0 0" xyz="0.322 0.03 0.551"/>
    <axis xyz="0 1 0"/>
    <limit effort="6300" lower="-1.134" upper="1.4855" velocity="1.5707"/>
    <dynamics damping="1.0" friction="0.0"/>
    <parent link="lwr_1_link"/>
    <child link="lwr_2_link"/>
  </joint>
  <joint name="lwr_2_joint" type="revolute">
    <origin rpy="0 0 0" xyz="0 0 1.075"/>
    <axis xyz="0 1 0"/>
    <limit effort="6500" lower="-3.142" upper="1.222" velocity="1.5707"/>
    <dynamics damping="1.0" friction="0.0"/>
    <parent link="lwr_2_link"/>
    <child link="lwr_3_link"/>
  </joint>
  <joint name="lwr_3_joint" type="revolute">
    <origin rpy="0 0 0" xyz="0 0 0.2"/>
    <axis xyz="1 0 0"/>
    <limit effort="990" lower="-5.236" upper="5.236" velocity="2.9671"/>
    <dynamics damping="1.0" friction="0.0"/>
    <parent link="lwr_3_link"/>
    <child link="lwr_4_link"/>
  </joint>
  <joint name="lwr_4_joint" type="revolute">
    <origin rpy="0 0 0" xyz="1.392 0 0"/>
    <axis xyz="0 1 0"/>
    <limit effort="1300" lower="-2.094" upper="2.094" velocity="2.4435"/>
    <dynamics damping="1.0" friction="0.0"/>
    <parent link="lwr_4_link"/>
    <child link="lwr_5_link"/>
  </joint>
  <joint name="lwr_5_joint" type="revolute">
    <origin rpy="0 0 0" xyz="0.153 0 0"/>
    <axis xyz="1 0 0"/>
    <limit effort="500" lower="-6.283" upper="6.283" velocity="3.3161"/>
    <dynamics damping="1.0" friction="0.0"/>
    <parent link="lwr_5_link"/>
    <child link="lwr_6_link"/>
  </joint>
  <joint name="joint_cylinder" type="fixed">
    <origin rpy="0 -0.170 0" xyz="-0.365 -0.1895 0.405"/>
    <parent link="lwr_1_link"/>
    <child link="link_cylinder"/>
  </joint>

  <!-- ###################################################### -->

  <transmission name="lwr_0_trans">
    <type>transmission_interface/SimpleTransmission</type>
    <joint name="lwr_0_joint">
      <hardwareInterface>PositionJointInterface</hardwareInterface>
      <hardwareInterface>EffortJointInterface</hardwareInterface>
    </joint>
    <actuator name="lwr_0_motor">
      <mechanicalReduction>1</mechanicalReduction>
    </actuator>
  </transmission>
  <transmission name="lwr_1_trans">
    <type>transmission_interface/SimpleTransmission</type>
    <joint name="lwr_1_joint">
      <hardwareInterface>PositionJointInterface</hardwareInterface>
      <hardwareInterface>EffortJointInterface</hardwareInterface>
    </joint>
    <actuator name="lwr_1_motor">
      <mechanicalReduction>1</mechanicalReduction>
    </actuator>
  </transmission>
  <transmission name="lwr_2_trans">
    <type>transmission_interface/SimpleTransmission</type>
    <joint name="lwr_2_joint">
      <hardwareInterface>PositionJointInterface</hardwareInterface>
      <hardwareInterface>EffortJointInterface</hardwareInterface>
    </joint>
    <actuator name="lwr_2_motor">
      <mechanicalReduction>1</mechanicalReduction>
    </actuator>
  </transmission>
  <transmission name="lwr_3_trans">
    <type>transmission_interface/SimpleTransmission</type>
    <joint name="lwr_3_joint">
      <hardwareInterface>PositionJointInterface</hardwareInterface>
      <hardwareInterface>EffortJointInterface</hardwareInterface>
    </joint>
    <actuator name="lwr_3_motor">
      <mechanicalReduction>1</mechanicalReduction>
    </actuator>
  </transmission>
  <transmission name="lwr_4_trans">
    <type>transmission_interface/SimpleTransmission</type>
    <joint name="lwr_4_joint">
      <hardwareInterface>PositionJointInterface</hardwareInterface>
      <hardwareInterface>EffortJointInterface</hardwareInterface>
    </joint>
    <actuator name="lwr_4_motor">
      <mechanicalReduction>1</mechanicalReduction>
    </actuator>
  </transmission>
  <transmission name="lwr_5_trans">
    <type>transmission_interface/SimpleTransmission</type>
    <joint name="lwr_5_joint">
      <hardwareInterface>PositionJointInterface</hardwareInterface>
      <hardwareInterface>EffortJointInterface</hardwareInterface>
    </joint>
    <actuator name="lwr_5_motor">
      <mechanicalReduction>1</mechanicalReduction>
    </actuator>
  </transmission>

</robot>
