<?xml version="1.0" ?>
<robot name="abb_irb6640" xmlns:xacro="http://ros.org/wiki/xacro">

  <link name="world"/>
  <!-- ################################################ -->
  <joint name="arm_to_world_fixed" type="fixed">
    <origin rpy="0 0 0" xyz="0 0 0"/>
    <parent link="world"/>
    <child link="support"/>
  </joint>
  <!-- ################################################ -->
  <link name="support">
    <visual>
      <origin rpy="0 0 0" xyz="0 0 0.05"/>
      <geometry>
        <box size="1 1 0.05"/>
      </geometry>
    </visual>
    <collision>
      <origin rpy="0 0 0" xyz="0 0 0.05"/>
      <geometry>
        <box size="1 1 0.05"/>
      </geometry>
    </collision>
    <inertial>
      <mass value="92.5052"/>
      <inertia ixx="1.0" ixy="1.0" ixz="1.0" iyy="1.0" iyz="1.0" izz="1.0"/>
    </inertial>
  </link>
  <joint name="base_joint_support" type="fixed">
    <origin rpy="0 0 0" xyz="0 0 0.05"/>
    <parent link="support"/>
    <child link="lwr_base_link"/>
  </joint>
  <!-- ################################################ -->
  <link name="lwr_base_link">
    <inertial>
      <mass value="500"/>
      <origin xyz="0 0 0.055"/>
      <inertia ixx="0.00305333333333" ixy="0" ixz="0" iyy="0.00288" iyz="0" izz="0.00305333333333"/>
    </inertial>
    <visual>
      <origin rpy="0 0 0" xyz="0 0 0 "/>
      <geometry>
        <mesh filename="/home/geekayman/based_on_flobaroid/model/meshes/irb6640_185_280/collision/base_link.stl"/>
      </geometry>
      <material name="">
        <color rgba="0.7372549 0.3490196 0.1607843 1"/>
      </material>
    </visual>
    <collision>
      <origin rpy="0 0 0" xyz="0 0 0"/>
      <geometry>
        <mesh filename="/home/geekayman/based_on_flobaroid/model/meshes/irb6640_185_280/collision/base_link.stl"/>
      </geometry>
    </collision>
  </link>
  <!-- ################################################ -->
  <joint name="lwr_0_joint" type="revolute">
    <origin rpy="0 0 0" xyz="0 0 0.780"/>
    <axis xyz="0 0 1"/>
    <limit effort="1000" lower="-2.967" upper="2.967" velocity="1.7453"/>
    <dynamics damping="1.0" friction="0.0"/>
    <parent link="lwr_base_link"/>
    <child link="lwr_1_link"/>
  </joint>
  <!-- ################################################ -->
  <link name="lwr_1_link">
    <inertial>
      <mass value="411"/>
      <origin rpy="0 0 0" xyz="0 -0.06 0.130"/>
      <inertia ixx="0.1315" ixy="0.001" ixz="0.001" iyy="0.1415" iyz="0.001" izz="0.02"/>
    </inertial>
    <visual>
      <origin rpy="0 0 0" xyz="0 0 0"/>
      <geometry>
        <mesh filename="/home/geekayman/based_on_flobaroid/model/meshes/irb6640_185_280/collision/link_1.stl"/>
      </geometry>
      <material name="">
        <color rgba="0.7372549 0.3490196 0.1607843 1"/>
      </material>
    </visual>
    <collision>
      <origin rpy="0 0 0" xyz="0 0 0"/>
      <geometry>
        <mesh filename="/home/geekayman/based_on_flobaroid/model/meshes/irb6640_185_280/collision/link_1.stl"/>
      </geometry>
    </collision>
  </link>
  <!-- ################################################ -->
  <joint name="lwr_1_joint" type="revolute">
    <origin rpy="0 0 0" xyz="0.320 0 0"/>
    <axis xyz="0 1 0"/>
    <limit effort="1000" lower="-1.134" upper="1.4855" velocity="1.5707"/>
    <dynamics damping="1.0" friction="0.0"/>
    <parent link="lwr_1_link"/>
    <child link="lwr_2_link"/>
  </joint>
  <!-- ################################################ -->
  <link name="lwr_2_link">
    <inertial>
      <mass value="121"/>
      <origin rpy="0 0 0" xyz="0 0.06 0.07"/>
      <inertia ixx="0.02" ixy="0.001" ixz="0.001" iyy="0.3962" iyz="0.001" izz="0.3952"/>
    </inertial>
    <visual>
      <origin rpy="0 0 0" xyz="0 0 0"/>
      <geometry>
        <mesh filename="/home/geekayman/based_on_flobaroid/model/meshes/irb6640_185_280/collision/link_2.stl"/>
      </geometry>
      <material name="">
        <color rgba="0.7372549 0.3490196 0.1607843 1"/>
      </material>
    </visual>
    <collision>
      <origin rpy="0 0 0" xyz="0 0 0"/>
      <geometry>
        <mesh filename="/home/geekayman/based_on_flobaroid/model/meshes/irb6640_185_280/collision/link_2.stl"/>
      </geometry>
    </collision>
  </link>
  <!-- ################################################ -->
  <joint name="lwr_2_joint" type="revolute">
    <origin rpy="0 0 0" xyz="0 0 1.075"/>
    <axis xyz="0 1 0"/>
    <limit effort="1000" lower="-3.142" upper="1.222" velocity="1.5707"/>
    <dynamics damping="1.0" friction="0.0"/>
    <parent link="lwr_2_link"/>
    <child link="lwr_3_link"/>
  </joint>
  <!-- ################################################ -->
  <link name="lwr_3_link">
    <inertial>
      <mass value="113.4"/>
      <origin rpy="0 0 0" xyz="0 0.06 0.130"/>
      <inertia ixx="0.045" ixy="0.001" ixz="0.001" iyy="0.04" iyz="0.001" izz="0.012"/>
    </inertial>
    <visual>
      <origin rpy="0 0 0" xyz="0 0 0"/>
      <geometry>
        <mesh filename="/home/geekayman/based_on_flobaroid/model/meshes/irb6640_185_280/collision/link_3.stl"/>
      </geometry>
      <material name="">
        <color rgba="0.7372549 0.3490196 0.1607843 1"/>
      </material>
    </visual>
    <collision>
      <origin rpy="0 0 0" xyz="0 0 0"/>
      <geometry>
        <mesh filename="/home/geekayman/based_on_flobaroid/model/meshes/irb6640_185_280/collision/link_3.stl"/>
      </geometry>
    </collision>
  </link>
  <!-- ################################################ -->
  <joint name="lwr_3_joint" type="revolute">
    <origin rpy="0 0 0" xyz="0 0 0.2"/>
    <axis xyz="1 0 0"/>
    <limit effort="1000" lower="-5.236" upper="5.236" velocity="2.9671"/>
    <dynamics damping="1.0" friction="0.0"/>
    <parent link="lwr_3_link"/>
    <child link="lwr_4_link"/>
  </joint>
  <!-- ################################################ -->
  <link name="lwr_4_link">
    <inertial>
      <mass value="74.6"/>
      <origin rpy="0 0 0" xyz="0 -0.06 0.07"/>
      <inertia ixx="0.437" ixy="0.001" ixz="0.001" iyy="0.447" iyz="0.001" izz="0.02"/>
    </inertial>
    <visual>
      <origin rpy="0 0 0" xyz="0 0 0"/>
      <geometry>
        <mesh filename="/home/geekayman/based_on_flobaroid/model/meshes/irb6640_185_280/collision/link_4.stl"/>
      </geometry>
      <material name="">
        <color rgba="0.7372549 0.3490196 0.1607843 1"/>
      </material>
    </visual>

    <collision>
      <origin rpy="0 0 0" xyz="0 0 0"/>
      <geometry>
        <mesh filename="/home/geekayman/based_on_flobaroid/model/meshes/irb6640_185_280/collision/link_4.stl"/>
      </geometry>
    </collision>
  </link>
  <!-- ################################################ -->
  <joint name="lwr_4_joint" type="revolute">
    <origin rpy="0 0 0" xyz="1.392 0 0"/>
    <axis xyz="0 1 0"/>
    <limit effort="1000" lower="-2.094" upper="2.094" velocity="2.4435"/>
    <dynamics damping="1.0" friction="0.0"/>
    <parent link="lwr_4_link"/>
    <child link="lwr_5_link"/>
  </joint>
  <!-- ################################################ -->
  <link name="lwr_5_link">
    <inertial>
      <mass value="24.6"/>
      <origin rpy="0 0 0" xyz="0 0 0.124"/>
      <inertia ixx="0.0133" ixy="0.001" ixz="0.001" iyy="0.025" iyz="0.001" izz="0.02"/>
    </inertial>
    <visual>
      <origin rpy="0 0 0" xyz="0 0 0"/>
      <geometry>
        <mesh filename="/home/geekayman/based_on_flobaroid/model/meshes/irb6640_185_280/collision/link_5.stl"/>
      </geometry>
      <material name="">
        <color rgba="0.7372549 0.3490196 0.1607843 1"/>
      </material>
    </visual>
    <collision>
      <origin rpy="0 0 0" xyz="0 0 0"/>
      <geometry>
        <mesh filename="/home/geekayman/based_on_flobaroid/model/meshes/irb6640_185_280/collision/link_5.stl"/>
      </geometry>
    </collision>
  </link>
  <!-- ################################################ -->
  <joint name="lwr_5_joint" type="revolute">
    <origin rpy="0 0 0" xyz="0.2 0 0"/>
    <axis xyz="1 0 0"/>
    <limit effort="1000" lower="-6.283" upper="6.283" velocity="3.3161"/>
    <dynamics damping="1.0" friction="0.0"/>
    <parent link="lwr_5_link"/>
    <child link="lwr_6_link"/>
  </joint>
  <!-- ################################################ -->
  <link name="lwr_6_link">
    <inertial>
      <mass value="5"/>
      <origin rpy="0 0 0" xyz="0 0 0.0625"/>
      <inertia ixx="0.02" ixy="0.001" ixz="0.001" iyy="0.02" iyz="0.001" izz="0.02"/>
    </inertial>
    <visual>
      <origin rpy="0 0 0" xyz="0 0 0"/>
      <geometry>
        <mesh filename="/home/geekayman/based_on_flobaroid/model/meshes/irb6640_185_280/collision/link_6.stl"/>
      </geometry>
      <material name="">
        <color rgba="0.5 0.5 0.5 1"/>
      </material>
    </visual>
    <collision>
      <origin rpy="0 0 0" xyz="0 0 0"/>
      <geometry>
        <mesh filename="/home/geekayman/based_on_flobaroid/model/meshes/irb6640_185_280/collision/link_6.stl"/>
      </geometry>
    </collision>
  </link>


  <transmission name="lwr_0_trans">
    <type>transmission_interface/SimpleTransmission</type>
    <joint name="lwr_0_joint">
      <hardwareInterface>PositionJointInterface</hardwareInterface>
      <hardwareInterface>EffortJointInterface</hardwareInterface>
    </joint>
    <actuator name="lwr_0_motor">
      <mechanicalReduction>1</mechanicalReduction>
    </actuator>
  </transmission>
  <transmission name="lwr_1_trans">
    <type>transmission_interface/SimpleTransmission</type>
    <joint name="lwr_1_joint">
      <hardwareInterface>PositionJointInterface</hardwareInterface>
      <hardwareInterface>EffortJointInterface</hardwareInterface>
    </joint>
    <actuator name="lwr_1_motor">
      <mechanicalReduction>1</mechanicalReduction>
    </actuator>
  </transmission>
  <transmission name="lwr_2_trans">
    <type>transmission_interface/SimpleTransmission</type>
    <joint name="lwr_2_joint">
      <hardwareInterface>PositionJointInterface</hardwareInterface>
      <hardwareInterface>EffortJointInterface</hardwareInterface>
    </joint>
    <actuator name="lwr_2_motor">
      <mechanicalReduction>1</mechanicalReduction>
    </actuator>
  </transmission>
  <transmission name="lwr_3_trans">
    <type>transmission_interface/SimpleTransmission</type>
    <joint name="lwr_3_joint">
      <hardwareInterface>PositionJointInterface</hardwareInterface>
      <hardwareInterface>EffortJointInterface</hardwareInterface>
    </joint>
    <actuator name="lwr_3_motor">
      <mechanicalReduction>1</mechanicalReduction>
    </actuator>
  </transmission>
  <transmission name="lwr_4_trans">
    <type>transmission_interface/SimpleTransmission</type>
    <joint name="lwr_4_joint">
      <hardwareInterface>PositionJointInterface</hardwareInterface>
      <hardwareInterface>EffortJointInterface</hardwareInterface>
    </joint>
    <actuator name="lwr_4_motor">
      <mechanicalReduction>1</mechanicalReduction>
    </actuator>
  </transmission>
  <transmission name="lwr_5_trans">
    <type>transmission_interface/SimpleTransmission</type>
    <joint name="lwr_5_joint">
      <hardwareInterface>PositionJointInterface</hardwareInterface>
      <hardwareInterface>EffortJointInterface</hardwareInterface>
    </joint>
    <actuator name="lwr_5_motor">
      <mechanicalReduction>1</mechanicalReduction>
    </actuator>
  </transmission>
</robot>
